Workbook

Sheet 封面
A1: UTTEC 有創科技｜議題研究總表
A2: 兩條研究線合併交付
A4: 產出日期：2026-09-19
A6: 線 A｜議題樹 344 條 16 個群集
A7: 從產業議題出發。讀者是已經有問題意識的人，作用是承接需求。
A8: 欄位：編號｜群集｜主題｜對象｜意圖｜建議平台｜收口層級｜優先序
A10: 線 C｜生活滲透 510 條 30 個群集
A11: 從生活出發。讀者是還不知道自己需要的人，作用是創造認知。
A12: 欄位：編號｜生活群集｜議題標題｜切入形式｜國際技術錨點｜間接帶入點｜建議平台｜層級
A13: 411 條（81%）帶有可查證的國際技術錨點。
A15: 合計 854 條議題
A17: 發布前五條硬限制
... A27: 以 Excel 或 Google 試算表開啟時會自動計算。所有數字已另以 Python 獨立核對。

Sheet 線A-議題樹344
A1: 編號 | B1: 群集 | C1: 主題 | D1: 對象 | E1: 意圖 | F1: 建議平台 | G1: 收口層級 | H1: 優先序
A2: A1-01 | B2: A1 走失預防與協尋實務 | C2: 長輩走失的第一個小時，該做的 7 件事（報案三不：不用等、不用跑、不用錢） | D2: 家屬 | E2: 急救型搜尋 | F2: 部落格／Threads | G2: L0 | H2: P1
A3: A1-02 | B3: A1 走失預防與協尋實務 | C3: 報案前先準備好這 6 樣東西，協尋速度差很多 | D3: 家屬 | E3: 實用清單 | F3: FB 社團 | G3: L0 | H3: P1
A4: A1-03 | B4: A1 走失預防與協尋實務 | C4: 「愛的手鍊」怎麼申請？要錢嗎？誰可以申請？ | D4: 家屬／照顧者 | E4: 資訊型 | F4: 部落格／IG | G4: L0 | H4: P1
A5: A1-04 | B5: A1 走失預防與協尋實務 | C5: 愛的手鍊 vs 定位器：不是二選一，而是兩層防護 | D5: 家屬 | E5: 比較型 | F5: 部落格 | G5: L1 | H5: P2
A6: A1-05 | B6: A1 走失預防與協尋實務 | C6: 指紋捺印要去哪裡辦？流程與注意事項 | D6: 家屬 | E6: 資訊型 | F6: 部落格 | G6: L0 | H6: P3
A7: A1-06 | B7: A1 走失預防與協尋實務 | C7: 衣物縫名條的正確寫法（為什麼不該寫全名和地址） | D7: 照顧者 | E7: 冷知識 | F7: Threads／IG | G7: L0 | H7: P2
A8: A1-07 | B8: A1 走失預防與協尋實務 | C8: 失智長輩走失最常發生的 5 個時間點 | D8: 家屬 | E8: 洞察型 | F8: Threads | G8: L0 | H8: P1
A9: A1-08 | B9: A1 走失預防與協尋實務 | C9: 走失熱點地圖：超商、公園、廟口、車站、舊家 | D9: 家屬 | E9: 洞察型 | F9: 部落格 | G9: L0 | H9: P3
A10: A1-09 | B10: A1 走失預防與協尋實務 | C10: 從家裡到菜市場那 300 公尺，才是風險最高的一段 | D10: 家屬 | E10: 故事型 | F10: Threads／FB | G10: L1 | H10: P2
A11: A1-10 | B11: A1 走失預防與協尋實務 | C11: 鄰里守望：跟這 7 家店打過招呼，找人快一倍 | D11: 照顧者 | E11: 實用 | F11: FB 社團 | G11: L0 | H11: P3
A12: A1-11 | B12: A1 走失預防與協尋實務 | C12: 里長、社區保全、管理員能幫你什麼（多數人沒用到） | D12: 照顧者 | E12: 資訊 | F12: 部落格 | G12: L0 | H12: P3
... A345: A16-20 | B345: A16 留存轉介與口碑 | C345: 三年之後，這個客戶還在嗎（留存的真實樣貌） | D345: 全 | E345: 長期視角 | F345: LinkedIn | G345: L1 | H345: P2

Sheet 線C-生活滲透510
A1: 編號 | B1: 生活群集 | C1: 議題標題 | D1: 切入形式 | E1: 國際技術錨點 | F1: 間接帶入點 | G1: 建議平台 | H1: 層級
A2: C01-01 | B2: C01 上班族與通勤 | C2: 你一年花多少時間在找東西？（30 秒問卷） | D2: 問卷調查 | E2: Apple Find My｜Tile | F2: 找東西的時間成本，是所有定位需求的共同起點 | G2: Threads／IG | H2: L0
A3: C01-02 | B3: C01 上班族與通勤 | C3: 辦公室最常不見的五樣東西排行 | D3: 市場調查 | E3: Google Find Hub｜Tile | F3: 資產定位不是工廠專利，辦公室也適用 | G3: Threads | H3: L0
A4: C01-03 | B4: C01 上班族與通勤 | C4: 我在捷運上撿到一個小圓片，它把我嚇到了 | D4: 個人發現 | E4: Apple AirTag｜IETF DULT 反追蹤標準 | F4: 反追蹤警示怎麼運作，順勢談匿名回傳設計 | G4: Threads／Dcard | H4: L1
A5: C01-04 | B5: C01 上班族與通勤 | C5: 通勤族的鑰匙掉落熱點地圖 | D5: 現象觀察 | E5: Apple Find My 群眾網路 | F5: 群眾網路在人多的地方才有用，這是誠實的前提 | G5: Threads | H5: L1
A6: C01-05 | B6: C01 上班族與通勤 | C6: 為什麼你的手機可能正在幫陌生人找東西 | D6: 冷知識 | E6: Apple Find My｜Google Find Hub | F6: 群眾網路的原理與匿名性，台灣也有自研版本 | G6: Mobile01／Threads | H6: L1
A7: C01-06 | B7: C01 上班族與通勤 | C7: 筆電被偷之後，我學到的三件事 | D7: 個人發現 | E7: Find My｜Find Hub | F7: 被動定位的極限與適用情境 | G7: Dcard | H7: L1
A8: C01-07 | B8: C01 上班族與通勤 | C8: 公司財產編號貼紙，為什麼永遠對不上 | D8: 現象觀察 | E8: BLE 資產標籤 | F8: 盤點從人工走到自動的那一步 | G8: LinkedIn | H8: L1
A9: C01-08 | B9: C01 上班族與通勤 | C9: 開放式辦公室，東西為什麼更容易不見 | D9: 社會現狀 | E9: BLE AoA/AoD 區域判讀 | F9: 區域級定位就夠用，不需要公分級 | G9: LinkedIn | H9: L2
A10: C01-09 | B10: C01 上班族與通勤 | C10: 會議室的投影轉接頭都去哪了 | D10: 現象觀察 | E10: Tile｜BLE 標籤 | F10: 小資產的流失成本被嚴重低估 | G10: Threads | H10: L0
A11: C01-10 | B11: C01 上班族與通勤 | C11: 遠距辦公後，公司設備追不回來的比例 | D11: 市場調查 | E11: Find My｜企業 MDM | F11: 離開場域之後就失去視野，這是普遍問題 | G11: LinkedIn | H11: L1
A12: C01-11 | B12: C01 上班族與通勤 | C12: 你願意讓公司知道你在哪嗎？（匿名投票） | D12: 問卷調查 | E12: 去識別化群體統計 | F12: 人員定位的倫理界線 | G12: Dcard／Threads | H12: L0
... A511: C30-17 | B511: C30 世代觀察與社會現象 | C511: 十年後，我們希望被怎麼照顧 | D511: 問卷調查 | E511: — | F511: 最有共鳴的收尾題 | G511: Threads | H511: L0

Sheet 統計
A1: 兩線合併統計
A3: 線 A 題數 | B3: =COUNTA('線A-議題樹344'!A2:A345)
A4: 線 C 題數 | B4: =COUNTA('線C-生活滲透510'!A2:A511)
A5: 合計 | B5: =B3+B4
A6: 線 C 帶國際技術錨點 | B6: =COUNTIF('線C-生活滲透510'!E2:E511,"<>—")
A8: 線 A 群集 | B8: 題數 | C8: P1 首波
A9: A1 走失預防與協尋實務 | B9: =COUNTIF('線A-議題樹344'!$B$2:$B$345,$A9) | C9: =COUNTIFS('線A-議題樹344'!$B$2:$B$345,$A9,'線A-議題樹344'!$H$2:$H$345,"P1")
A10: A2 補助政策與申請流程 | B10: =COUNTIF('線A-議題樹344'!$B$2:$B$345,$A10) | C10: =COUNTIFS('線A-議題樹344'!$B$2:$B$345,$A10,'線A-議題樹344'!$H$2:$H$345,"P1")
A11: A3 照顧者日常與家庭溝通 | B11: =COUNTIF('線A-議題樹344'!$B$2:$B$345,$A11) | C11: =COUNTIFS('線A-議題樹344'!$B$2:$B$345,$A11,'線A-議題樹344'!$H$2:$H$345,"P1")
A12: A4 定位輔具選購與比較 | B12: =COUNTIF('線A-議題樹344'!$B$2:$B$345,$A12) | C12: =COUNTIFS('線A-議題樹344'!$B$2:$B$345,$A12,'線A-議題樹344'!$H$2:$H$345,"P1")
A13: A5 長照機構與日照導入 | B13: =COUNTIF('線A-議題樹344'!$B$2:$B$345,$A13) | C13: =COUNTIFS('線A-議題樹344'!$B$2:$B$345,$A13,'線A-議題樹344'!$H$2:$H$345,"P1")
A14: A6 工廠工安與人員資產定位 | B14: =COUNTIF('線A-議題樹344'!$B$2:$B$345,$A14) | C14: =COUNTIFS('線A-議題樹344'!$B$2:$B$345,$A14,'線A-議題樹344'!$H$2:$H$345,"P1")
A15: A7 物流倉儲與冷鏈 | B15: =COUNTIF('線A-議題樹344'!$B$2:$B$345,$A15) | C15: =COUNTIFS('線A-議題樹344'!$B$2:$B$345,$A15,'線A-議題樹344'!$H$2:$H$345,"P1")
A16: A8 醫院設備與病患安全 | B16: =COUNTIF('線A-議題樹344'!$B$2:$B$345,$A16) | C16: =COUNTIFS('線A-議題樹344'!$B$2:$B$345,$A16,'線A-議題樹344'!$H$2:$H$345,"P1")
A17: A9 定位技術科普與選型 | B17: =COUNTIF('線A-議題樹344'!$B$2:$B$345,$A17) | C17: =COUNTIFS('線A-議題樹344'!$B$2:$B$345,$A17,'線A-議題樹344'!$H$2:$H$345,"P1")
A18: A10 隱私倫理與社會議題 | B18: =COUNTIF('線A-議題樹344'!$B$2:$B$345,$A18) | C18: =COUNTIFS('線A-議題樹344'!$B$2:$B$345,$A18,'線A-議題樹344'!$H$2:$H$345,"P1")
A19: A11 通路與經銷商 | B19: =COUNTIF('線A-議題樹344'!$B$2:$B$345,$A19) | C19: =COUNTIFS('線A-議題樹344'!$B$2:$B$345,$A19,'線A-議題樹344'!$H$2:$H$345,"P1")
A20: A12 政策與制度解讀 | B20: =COUNTIF('線A-議題樹344'!$B$2:$B$345,$A20) | C20: =COUNTIFS('線A-議題樹344'!$B$2:$B$345,$A20,'線A-議題樹344'!$H$2:$H$345,"P1")
... A24: A16 留存轉介與口碑 | B24: =COUNTIF('線A-議題樹344'!$B$2:$B$345,$A24) | C24: =COUNTIFS('線A-議題樹344'!$B$2:$B$345,$A24,'線A-議題樹344'!$H$2:$H$345,"P1")
A25: 小計 | B25: =SUM(B9:B24) | C25: =SUM(C9:C24)
A27: 線 C 生活群集 | B27: 題數
A28: C01 上班族與通勤 | B28: =COUNTIF('線C-生活滲透510'!$B$2:$B$511,$A28)
A29: C02 家庭育兒與學齡兒童 | B29: =COUNTIF('線C-生活滲透510'!$B$2:$B$511,$A29)
A30: C03 寵物與毛小孩 | B30: =COUNTIF('線C-生活滲透510'!$B$2:$B$511,$A30)
A31: C04 校園與補教 | B31: =COUNTIF('線C-生活滲透510'!$B$2:$B$511,$A31)
A32: C05 運動健身與路跑 | B32: =COUNTIF('線C-生活滲透510'!$B$2:$B$511,$A32)
A33: C06 登山露營與戶外 | B33: =COUNTIF('線C-生活滲透510'!$B$2:$B$511,$A33)
A34: C07 旅遊住宿與行李 | B34: =COUNTIF('線C-生活滲透510'!$B$2:$B$511,$A34)
A35: C08 餐飲外送與廚房 | B35: =COUNTIF('線C-生活滲透510'!$B$2:$B$511,$A35)
A36: C09 零售賣場與百貨 | B36: =COUNTIF('線C-生活滲透510'!$B$2:$B$511,$A36)
A37: C10 傳統市場與攤商 | B37: =COUNTIF('線C-生活滲透510'!$B$2:$B$511,$A37)
A38: C11 建築工地與職人 | B38: =COUNTIF('線C-生活滲透510'!$B$2:$B$511,$A38)
A39: C12 農林漁牧 | B39: =COUNTIF('線C-生活滲透510'!$B$2:$B$511,$A39)
... A57: C30 世代觀察與社會現象 | B57: =COUNTIF('線C-生活滲透510'!$B$2:$B$511,$A57)
A58: 小計 | B58: =SUM(B28:B57)
A60: 線 C 切入形式 | B60: 題數
A61: 現象觀察 | B61: =COUNTIF('線C-生活滲透510'!$D$2:$D$511,$A61)
A62: 市場調查 | B62: =COUNTIF('線C-生活滲透510'!$D$2:$D$511,$A62)
A63: 社會現狀 | B63: =COUNTIF('線C-生活滲透510'!$D$2:$D$511,$A63)
A64: 冷知識 | B64: =COUNTIF('線C-生活滲透510'!$D$2:$D$511,$A64)
...
